<?xml version="1.0" encoding="UTF-8"?>
<!-- Generated by org.testng.reporters.JUnitReportReporter -->
<testsuite hostname="Skylark.local" name="hub.test.endtoend.EndToEnd_SmokeTest" tests="18" failures="0" timestamp="4 Sep 2014 07:55:25 GMT" time="578.673" errors="3">
  <testcase name="testLogin" time="106.804" classname="hub.test.endtoend.EndToEnd_SmokeTest">
    <error type="java.lang.AssertionError" message="Exception was thrown">
      <![CDATA[java.lang.AssertionError: Exception was thrown
	at org.testng.Assert.fail(Assert.java:94)
	at hub.test.endtoend.EndToEnd_SmokeTest.testLogin(EndToEnd_SmokeTest.java:151)
	at sun.reflect.GeneratedMethodAccessor8.invoke(Unknown Source)
	at sun.reflect.DelegatingMethodAccessorImpl.invoke(DelegatingMethodAccessorImpl.java:43)
	at java.lang.reflect.Method.invoke(Method.java:601)
	at org.testng.internal.MethodInvocationHelper.invokeMethod(MethodInvocationHelper.java:84)
	at org.testng.internal.Invoker.invokeMethod(Invoker.java:714)
	at org.testng.internal.Invoker.invokeTestMethod(Invoker.java:901)
	at org.testng.internal.Invoker.invokeTestMethods(Invoker.java:1231)
	at org.testng.internal.TestMethodWorker.invokeTestMethods(TestMethodWorker.java:127)
	at org.testng.internal.TestMethodWorker.run(TestMethodWorker.java:111)
	at org.testng.TestRunner.privateRun(TestRunner.java:767)
	at org.testng.TestRunner.run(TestRunner.java:617)
	at org.testng.SuiteRunner.runTest(SuiteRunner.java:335)
	at org.testng.SuiteRunner.runSequentially(SuiteRunner.java:330)
	at org.testng.SuiteRunner.privateRun(SuiteRunner.java:291)
	at org.testng.SuiteRunner.run(SuiteRunner.java:240)
	at org.testng.SuiteRunnerWorker.runSuite(SuiteRunnerWorker.java:52)
	at org.testng.SuiteRunnerWorker.run(SuiteRunnerWorker.java:86)
	at org.testng.TestNG.runSuitesSequentially(TestNG.java:1224)
	at org.testng.TestNG.runSuitesLocally(TestNG.java:1149)
	at org.testng.TestNG.run(TestNG.java:1057)
	at org.testng.remote.RemoteTestNG.run(RemoteTestNG.java:111)
	at org.testng.remote.RemoteTestNG.initAndRun(RemoteTestNG.java:204)
	at org.testng.remote.RemoteTestNG.main(RemoteTestNG.java:175)
]]>
    </error>
  </testcase> <!-- testLogin -->
  <testcase name="testLogin" time="39.043" classname="hub.test.endtoend.EndToEnd_SmokeTest"/>
  <testcase name="testLogin" time="16.190" classname="hub.test.endtoend.EndToEnd_SmokeTest"/>
  <testcase name="testLogin" time="3.388" classname="hub.test.endtoend.EndToEnd_SmokeTest"/>
  <testcase name="testLogin" time="3.199" classname="hub.test.endtoend.EndToEnd_SmokeTest"/>
  <testcase name="testLogin" time="14.497" classname="hub.test.endtoend.EndToEnd_SmokeTest"/>
  <testcase name="testLogin" time="31.983" classname="hub.test.endtoend.EndToEnd_SmokeTest">
    <error type="java.lang.AssertionError" message="Exception was thrown">
      <![CDATA[java.lang.AssertionError: Exception was thrown
	at org.testng.Assert.fail(Assert.java:94)
	at hub.test.endtoend.EndToEnd_SmokeTest.testLogin(EndToEnd_SmokeTest.java:151)
	at sun.reflect.NativeMethodAccessorImpl.invoke0(Native Method)
	at sun.reflect.NativeMethodAccessorImpl.invoke(NativeMethodAccessorImpl.java:57)
	at sun.reflect.DelegatingMethodAccessorImpl.invoke(DelegatingMethodAccessorImpl.java:43)
	at java.lang.reflect.Method.invoke(Method.java:601)
	at org.testng.internal.MethodInvocationHelper.invokeMethod(MethodInvocationHelper.java:84)
	at org.testng.internal.Invoker.invokeMethod(Invoker.java:714)
	at org.testng.internal.Invoker.invokeTestMethod(Invoker.java:901)
	at org.testng.internal.Invoker.invokeTestMethods(Invoker.java:1231)
	at org.testng.internal.TestMethodWorker.invokeTestMethods(TestMethodWorker.java:127)
	at org.testng.internal.TestMethodWorker.run(TestMethodWorker.java:111)
	at org.testng.TestRunner.privateRun(TestRunner.java:767)
	at org.testng.TestRunner.run(TestRunner.java:617)
	at org.testng.SuiteRunner.runTest(SuiteRunner.java:335)
	at org.testng.SuiteRunner.runSequentially(SuiteRunner.java:330)
	at org.testng.SuiteRunner.privateRun(SuiteRunner.java:291)
	at org.testng.SuiteRunner.run(SuiteRunner.java:240)
	at org.testng.SuiteRunnerWorker.runSuite(SuiteRunnerWorker.java:52)
	at org.testng.SuiteRunnerWorker.run(SuiteRunnerWorker.java:86)
	at org.testng.TestNG.runSuitesSequentially(TestNG.java:1224)
	at org.testng.TestNG.runSuitesLocally(TestNG.java:1149)
	at org.testng.TestNG.run(TestNG.java:1057)
	at org.testng.remote.RemoteTestNG.run(RemoteTestNG.java:111)
	at org.testng.remote.RemoteTestNG.initAndRun(RemoteTestNG.java:204)
	at org.testng.remote.RemoteTestNG.main(RemoteTestNG.java:175)
]]>
    </error>
  </testcase> <!-- testLogin -->
  <testcase name="testLogin" time="16.390" classname="hub.test.endtoend.EndToEnd_SmokeTest"/>
  <testcase name="testLogin" time="51.819" classname="hub.test.endtoend.EndToEnd_SmokeTest">
    <error type="java.lang.AssertionError" message="Exception was thrown">
      <![CDATA[java.lang.AssertionError: Exception was thrown
	at org.testng.Assert.fail(Assert.java:94)
	at hub.test.endtoend.EndToEnd_SmokeTest.testLogin(EndToEnd_SmokeTest.java:151)
	at sun.reflect.GeneratedMethodAccessor8.invoke(Unknown Source)
	at sun.reflect.DelegatingMethodAccessorImpl.invoke(DelegatingMethodAccessorImpl.java:43)
	at java.lang.reflect.Method.invoke(Method.java:601)
	at org.testng.internal.MethodInvocationHelper.invokeMethod(MethodInvocationHelper.java:84)
	at org.testng.internal.Invoker.invokeMethod(Invoker.java:714)
	at org.testng.internal.Invoker.invokeTestMethod(Invoker.java:901)
	at org.testng.internal.Invoker.invokeTestMethods(Invoker.java:1231)
	at org.testng.internal.TestMethodWorker.invokeTestMethods(TestMethodWorker.java:127)
	at org.testng.internal.TestMethodWorker.run(TestMethodWorker.java:111)
	at org.testng.TestRunner.privateRun(TestRunner.java:767)
	at org.testng.TestRunner.run(TestRunner.java:617)
	at org.testng.SuiteRunner.runTest(SuiteRunner.java:335)
	at org.testng.SuiteRunner.runSequentially(SuiteRunner.java:330)
	at org.testng.SuiteRunner.privateRun(SuiteRunner.java:291)
	at org.testng.SuiteRunner.run(SuiteRunner.java:240)
	at org.testng.SuiteRunnerWorker.runSuite(SuiteRunnerWorker.java:52)
	at org.testng.SuiteRunnerWorker.run(SuiteRunnerWorker.java:86)
	at org.testng.TestNG.runSuitesSequentially(TestNG.java:1224)
	at org.testng.TestNG.runSuitesLocally(TestNG.java:1149)
	at org.testng.TestNG.run(TestNG.java:1057)
	at org.testng.remote.RemoteTestNG.run(RemoteTestNG.java:111)
	at org.testng.remote.RemoteTestNG.initAndRun(RemoteTestNG.java:204)
	at org.testng.remote.RemoteTestNG.main(RemoteTestNG.java:175)
]]>
    </error>
  </testcase> <!-- testLogin -->
  <testcase name="testLogin" time="15.168" classname="hub.test.endtoend.EndToEnd_SmokeTest"/>
  <testcase name="testLogin" time="29.258" classname="hub.test.endtoend.EndToEnd_SmokeTest"/>
  <testcase name="testLogin" time="10.581" classname="hub.test.endtoend.EndToEnd_SmokeTest"/>
  <testcase name="testLogin" time="1.953" classname="hub.test.endtoend.EndToEnd_SmokeTest"/>
  <testcase name="testLogin" time="82.916" classname="hub.test.endtoend.EndToEnd_SmokeTest"/>
  <testcase name="testLogin" time="44.222" classname="hub.test.endtoend.EndToEnd_SmokeTest"/>
  <testcase name="testLogin" time="12.406" classname="hub.test.endtoend.EndToEnd_SmokeTest"/>
  <testcase name="testLogin" time="53.973" classname="hub.test.endtoend.EndToEnd_SmokeTest"/>
  <testcase name="testLogin" time="44.883" classname="hub.test.endtoend.EndToEnd_SmokeTest"/>
</testsuite> <!-- hub.test.endtoend.EndToEnd_SmokeTest -->
