<?xml version="1.0" encoding="UTF-8"?>
<!-- Generated by org.testng.reporters.JUnitReportReporter -->
<testsuite hostname="Crow.local" name="hub.test.UserResetPasswordTest" tests="7" failures="0" timestamp="6 Feb 2014 02:33:46 GMT" time="80.719" errors="1">
  <testcase name="testLogin" time="6.699" classname="hub.test.UserResetPasswordTest"/>
  <testcase name="testLogin" time="5.831" classname="hub.test.UserResetPasswordTest"/>
  <testcase name="testLogin" time="6.541" classname="hub.test.UserResetPasswordTest"/>
  <testcase name="testLogin" time="43.541" classname="hub.test.UserResetPasswordTest">
    <error type="java.lang.AssertionError" message="Exception was thrown">
      <![CDATA[java.lang.AssertionError: Exception was thrown
	at org.testng.Assert.fail(Assert.java:94)
	at hub.test.UserResetPasswordTest.testLogin(UserResetPasswordTest.java:53)
	at sun.reflect.NativeMethodAccessorImpl.invoke0(Native Method)
	at sun.reflect.NativeMethodAccessorImpl.invoke(NativeMethodAccessorImpl.java:57)
	at sun.reflect.DelegatingMethodAccessorImpl.invoke(DelegatingMethodAccessorImpl.java:43)
	at java.lang.reflect.Method.invoke(Method.java:601)
	at org.testng.internal.MethodInvocationHelper.invokeMethod(MethodInvocationHelper.java:84)
	at org.testng.internal.Invoker.invokeMethod(Invoker.java:714)
	at org.testng.internal.Invoker.invokeTestMethod(Invoker.java:901)
	at org.testng.internal.Invoker.invokeTestMethods(Invoker.java:1231)
	at org.testng.internal.TestMethodWorker.invokeTestMethods(TestMethodWorker.java:127)
	at org.testng.internal.TestMethodWorker.run(TestMethodWorker.java:111)
	at org.testng.TestRunner.privateRun(TestRunner.java:767)
	at org.testng.TestRunner.run(TestRunner.java:617)
	at org.testng.SuiteRunner.runTest(SuiteRunner.java:334)
	at org.testng.SuiteRunner.runSequentially(SuiteRunner.java:329)
	at org.testng.SuiteRunner.privateRun(SuiteRunner.java:291)
	at org.testng.SuiteRunner.run(SuiteRunner.java:240)
	at org.testng.SuiteRunnerWorker.runSuite(SuiteRunnerWorker.java:52)
	at org.testng.SuiteRunnerWorker.run(SuiteRunnerWorker.java:86)
	at org.testng.TestNG.runSuitesSequentially(TestNG.java:1224)
	at org.testng.TestNG.runSuitesLocally(TestNG.java:1149)
	at org.testng.TestNG.run(TestNG.java:1057)
	at org.testng.remote.RemoteTestNG.run(RemoteTestNG.java:111)
	at org.testng.remote.RemoteTestNG.initAndRun(RemoteTestNG.java:204)
	at org.testng.remote.RemoteTestNG.main(RemoteTestNG.java:175)
]]>
    </error>
  </testcase> <!-- testLogin -->
  <testcase name="testLogin" time="5.964" classname="hub.test.UserResetPasswordTest"/>
  <testcase name="testLogin" time="6.331" classname="hub.test.UserResetPasswordTest"/>
  <testcase name="testLogin" time="5.812" classname="hub.test.UserResetPasswordTest"/>
</testsuite> <!-- hub.test.UserResetPasswordTest -->
